Workbook

Sheet Summary
A1: .trap | B1: =group!E12 -> 916 | C1: ="0x"&DEC2HEX(B1) -> 0x394 | F1: esp_image: segment 0: paddr=00010020 vaddr=3c000020 size=09c78h ( 40056) map | G1: =B8+B9 -> 40056 | H1: .rodata + .rodata_wifi
A2: .rwtext | B2: =group!E30 -> 1096 | C2: ="0x"&DEC2HEX(B2) -> 0x448 | F2: esp_image: segment 1: paddr=00019ce4 vaddr=3fc87460 size=0137ch ( 4988) load | G2: =B5+B6 -> 4988 | H2: .data + .data_wifi
A3: .rwtext_wifi | B3: ='.rwtext.wifi'!F192 -> 27780 | C3: ="0x"&DEC2HEX(B3) -> 0x6C84 | F3: esp_image: segment 2: paddr=0001b054 vaddr=40380000 size=04ff4h ( 20468) load | I3: 20468
A4: .rwdata_dummy | B4: =group!E12+group!E30+'.rwtext.wifi'!F192 -> 29792 | C4: ="0x"&DEC2HEX(B4) -> 0x7460 | F4: esp_image: segment 3: paddr=00020020 vaddr=42010020 size=4a3ach (304044) map | G4: =SUM(B12:B28)+12 -> 304044 | H4: .esp-riscv-rt + … + .text
A5: .data | B5: ='.data'!D77 -> 4496 | C5: ="0x"&DEC2HEX(B5) -> 0x1190 | D5: x | F5: esp_image: segment 4: paddr=00069384 vaddr=40384fc4 size=0246ch ( 9324) load | I5: 9324
A6: .data_wifi | B6: =group!E48 -> 492 | C6: ="0x"&DEC2HEX(B6) -> 0x1EC | D6: x | G6: =B1+B2+B3 -> 29792 | H6: .trap + .rwtext + .rwtext_wifi | I6: =I3+I5 -> 29792 | J6: =B4 -> 29792
A7: .bss | B7: ='.bss'!D210 -> 112552 | C7: ="0x"&DEC2HEX(B7) -> 0x1B7A8 | G7: =G1+G2+G4+G6 -> 378880
A8: .rodata | B8: ='.rodata'!D99 -> 13736 | C8: ="0x"&DEC2HEX(B8) -> 0x35A8 | D8: x | F8: flash usage | G8: =G1+G4 -> 344100
A9: .rodata_wifi | B9: 26320 | C9: ="0x"&DEC2HEX(B9) -> 0x66D0 | D9: x | F9: ram usage in image | G9: =G2+G6 -> 34780 | H9: =G8+G9 -> 378880
A10: .rotext_dummy | C10: 0x10000 | F10: ram for .bss | G10: =B7 -> 112552 | I10: full ram | J10: =G9+G10 -> 147332
F11: image headers | H11: …..........
A12: .esp-riscv-rt | B12: =group!E57 -> 210 | C12: ="0x"&DEC2HEX(B12) -> 0xD2 | F12: image size (espflash save-image --chip esp32c3 esp-wifi esp-wifi.img) | H12: 378.992
A13: .console | B13: =group!E62 -> 384 | C13: ="0x"&DEC2HEX(B13) -> 0x180 | D13: =B12+B13 -> 594 | F13: runtime
A14: .esp-hal | B14: ='.esp-hal'!C85 -> 8740 | C14: ="0x"&DEC2HEX(B14) -> 0x2224 | D14: =B14 -> 8740 | F14: HAL
A15: .embassy | B15: =embassy!D50 -> 5128 | C15: ="0x"&DEC2HEX(B15) -> 0x1408
A16: .esp-embassy | B16: =embassy!D58 -> 760 | C16: ="0x"&DEC2HEX(B16) -> 0x2F8 | D16: =B15+B16 -> 5888 | F16: embassy
A17: .esp-alloc | B17: ='alloc+atomic'!D18 -> 1876 | C17: ="0x"&DEC2HEX(B17) -> 0x754
A18: .port-atomic | B18: ='alloc+atomic'!D26 -> 156 | C18: ="0x"&DEC2HEX(B18) -> 0x9C | D18: =B17+B18 -> 2032 | F18: crates
A19: .esp-wifi | B19: ='.esp-wifi'!C146 -> 14438 | C19: ="0x"&DEC2HEX(B19) -> 0x3866 | D19: =B19 -> 14438 | F19: esp-wifi (shims)
A20: .libcore | B20: ='libcore printf'!D5 -> 368 | C20: ="0x"&DEC2HEX(B20) -> 0x170
A21: .libprintf | B21: ='libcore printf'!D18 -> 4644 | C21: ="0x"&DEC2HEX(B21) -> 0x1224
A22: .libpp | B22: ='.libpp'!E356 -> 36242 | C22: ="0x"&DEC2HEX(B22) -> 0x8D92
A23: .libphy | B23: ='.libphy'!E158 -> 29396 | C23: ="0x"&DEC2HEX(B23) -> 0x72D4
A24: .libnet80211 | B24: ='.libnet80211'!E681 -> 121568 | C24: ="0x"&DEC2HEX(B24) -> 0x1DAE0
A25: .libwpa-suppl | B25: ='.libwpa-suppl'!E379 -> 48494 | C25: ="0x"&DEC2HEX(B25) -> 0xBD6E | D25: =SUM(B20:B25) -> 240712 | F25: wifi libs
A26: .smoltcp | B26: ='.smoltcp'!C70 -> 26582 | C26: ="0x"&DEC2HEX(B26) -> 0x67D6 | D26: =B26 -> 26582 | F26: smoltcp
A27: .core | B27: ='core-text'!D25 -> 792 | C27: ="0x"&DEC2HEX(B27) -> 0x318
A28: .text | B28: ='core-text'!D34 -> 4254 | C28: ="0x"&DEC2HEX(B28) -> 0x109E
F30: SSID="iWIFI-2.4" PASSWORD="dingomolarsanta" cargo run --release
F31: cargo run --release
F32: UPDATED

Sheet group
A1: .trap
A2: 0x40380000 | B2: _start_trap:
A3: 0x40380024 | B3: _start_trap1:
A4: 0x40380032 | B4: _start_trap2:
A5: …
A6: 0x403801c8 | B6: _start_trap31: | C6: 478
A8: 0x403801de | B8: _start_trap_direct: | C8: 168
A9: 0x40380286 | B9: padding | C9: 122
A10: 0x40380300 | B10: _vector_table: | C10: 128
A11: 0x40380380 | B11: _start_trap_rust_hal: | C11: 18
A12: 0x40380392 | B12: padding | C12: 2 | E12: =SUM($C$2:C12) -> 916 | F12: ="0x"&DEC2HEX(E12) -> 0x394
A15: .rwtext
B16: esp_wifi::wifi::esp_wifi_tx_done_cb | C16: 214
B17: esp_wifi::common_adapter::semphr_take | C17: 8
B18: esp_wifi::common_adapter::semphr_give | C18: 40
B19: random | C19: 10
B21: interrupt1
B22: …
B23: interrupt15 | C23: 120
B25: handle_interrupts | C25: 432
B27: esp_hal::interrupt::riscv::classic::PRIORITY_TO_INTERRUPT | C27: 8
B28: esp_hal::interrupt::riscv::classic::INTERRUPT_TO_PRIORITY | C28: 16
B30: __EXTERNAL_INTERRUPTS | C30: 248 | E30: =SUM(C$16:$C30) -> 1096 | F30: ="0x"&DEC2HEX(E30) -> 0x448
A33: .data_wifi
D34: 3FC885D8
B35: libnet80211.a(ieee80211_mesh_quick.o):(.dram1.2) g_mesh_is_started | C35: 1 | D35: ="0x"&DEC2HEX(HEX2DEC(D$34)+SUM($C$35:C35)) -> 0x3FC885D9
B36: padding | C36: 3 | D36: ="0x"&DEC2HEX(HEX2DEC(D$34)+SUM($C$35:C36)) -> 0x3FC885DC
B37: libnet80211.a(ieee80211_mesh_quick.o):(.dram1.3) g_mesh_init_ps_type | C37: 4 | D37: ="0x"&DEC2HEX(HEX2DEC(D$34)+SUM($C$35:C37)) -> 0x3FC885E0
B38: libnet80211.a(ieee80211_mesh_quick.o):(.dram1.4) g_mesh_is_root | C38: 1 | D38: ="0x"&DEC2HEX(HEX2DEC(D$34)+SUM($C$35:C38)) -> 0x3FC885E1
B39: libnet80211.a(wl_cnx.o):(.dram1.2) g_sta_connected_flag | C39: 1 | D39: ="0x"&DEC2HEX(HEX2DEC(D$34)+SUM($C$35:C39)) -> 0x3FC885E2
B40: padding | C40: 2 | D40: ="0x"&DEC2HEX(HEX2DEC(D$34)+SUM($C$35:C40)) -> 0x3FC885E4
D41: ="0x"&DEC2HEX(HEX2DEC(D$34)+SUM($C$35:C41)) -> 0x3FC885E4
B42: libpp.a(esf_buf.o):(.dram1.3) eb_txdesc_space | C42: 144 | D42: ="0x"&DEC2HEX(HEX2DEC(D$34)+SUM($C$35:C42)) -> 0x3FC88674
B43: libpp.a(pp.o):(.dram1.3) pp_sig_cnt | C43: 33 | D43: ="0x"&DEC2HEX(HEX2DEC(D$34)+SUM($C$35:C43)) -> 0x3FC88695
B44: padding | C44: 3 | D44: ="0x"&DEC2HEX(HEX2DEC(D$34)+SUM($C$35:C44)) -> 0x3FC88698
B45: libpp.a(pp.o):(.dram1.4) bars | C45: 160 | D45: ="0x"&DEC2HEX(HEX2DEC(D$34)+SUM($C$35:C45)) -> 0x3FC88738
B46: libpp.a(pp_debug.o):(.dram1.3) | C46: 4 | D46: ="0x"&DEC2HEX(HEX2DEC(D$34)+SUM($C$35:C46)) -> 0x3FC8873C
B47: libpp.a(wdev.o):(.dram1.3) | C47: 4 | D47: ="0x"&DEC2HEX(HEX2DEC(D$34)+SUM($C$35:C47)) -> 0x3FC88740
B48: libpp.a(wdev.o):(.dram1.42) s_record_list | C48: 132 | D48: ="0x"&DEC2HEX(HEX2DEC(D$34)+SUM($C$35:C48)) -> 0x3FC887C4 | E48: =SUM(C$35:$C48) -> 492 | F48: ="0x"&DEC2HEX(E48) -> 0x1EC
A51: .esp_riscv_rt
...

Sheet .rwtext.wifi
A1: libpp.a
B2: esf_buf.o | H2: wifi_softap_cur_max_ap_bss_num | I2: 16
C3: .wifirxiram.9 | D3: esf_buf_recycle | E3: =I26 -> 324 | H3: ieee80211_encap_esfbuf | I3: 1302
C4: .wifiextrairam.5 | D4: esf_buf_alloc_dynamic | E4: =I139 -> 508 | H4: ieee80211_output_process | I4: 658
B5: if_hwctrl.o | H5: lmacMSDUAged | I5: 92
C6: .wifislprxiram.12 | D6: ic_mac_deinit | E6: =I36 -> 16 | H6: lmacAdjustTimestamp | I6: 76
B7: lmac.o | H7: lmacTxFrame | I7: 484
C8: .wifi0iram.41 | D8: lmacMSDUAged | E8: =I5 -> 92 | H8: lmacTxDone | I8: 244
C9: .wifi0iram.57 | D9: lmacAdjustTimestamp | E9: =I6 -> 76 | H9: lmacEndFrameExchangeSequence | I9: 788
C10: .wifi0iram.58 | D10: lmacTxFrame | E10: =I7 -> 484 | H10: pp_coex_tx_request | I10: 340
C11: .wifi0iram.62 | D11: lmacTxDone | E11: =I8 -> 244 | H11: ppMapTxQueue | I11: 336
C12: .wifi0iram.25 | D12: lmacEndFrameExchangeSequence | E12: =I9 -> 788 | H12: ppProcTxSecFrame | I12: 330
C13: .iram1.2 | D13: pm_get_null_max_tx_time | E13: =I121 -> 146 | H13: ppCalTxAMPDULength | I13: 748
C14: .wifiextrairam.5 | D14: lmacSetTxFrame | E14: =I140 -> 508 | H14: ppProcessLifeTime | I14: 176
C15: .wifiextrairam.23 | D15: lmacDiscardFrameExchangeSequence | E15: =I141 -> 222 | H15: rcUpdateTxDone | I15: 150
C16: .wifiextrairam.18 | D16: lmacProcessTxSuccess | E16: =I142 -> 264 | H16: rcGetSched | I16: 228
C17: .wifiextrairam.38 | D17: lmacProcessTxComplete | E17: =I143 -> 354 | H17: hal_mac_tx_config_timeout | I17: 38
B18: pm.o | H18: hal_mac_tx_config_edca | I18: 82
C19: .wifirxiram.48 | D19: pm_rx_data_process | E19: =I27 -> 138 | H19: hal_mac_txq_enable | I19: 26
C20: .wifirxiram.49 | D20: pm_hmac_rx_data_process | E20: =I28 -> 2 | H20: hal_random | I20: 8
C21: .wifislprxiram.6 | D21: pm_scale_listen_interval | E21: =I37 -> 216 | H21: hal_mac_deinit | I21: 64
C22: .wifislprxiram.25 | D22: pm_get_tbtt_count | E22: =I38 -> 176 | H22: hal_mac_tx_is_cbw40 | I22: 30
C23: .wifislprxiram.10 | D23: pm_parse_beacon | E23: =I39 -> 570 | H23: ieee80211_ampdu_reorder | I23: 630
C24: .wifislprxiram.26 | D24: pm_save_tbtt_info | E24: =I40 -> 34 | H24: sta_input | I24: 1378
C25: .wifislprxiram.28 | D25: pm_beacon_monitor_tbtt_start | E25: =I41 -> 190 | H25: sta_rx_cb | I25: 16
C26: .wifislprxiram.29 | D26: pm_beacon_monitor_tbtt_stop | E26: =I42 -> 18 | H26: esf_buf_recycle | I26: 324
C27: .wifislprxiram.30 | D27: pm_enable_beacon_monitor_timer | E27: =I43 -> 116 | H27: pm_rx_data_process | I27: 138
C28: .wifislprxiram.31 | D28: pm_disable_beacon_monitor_timer | E28: =I44 -> 60 | H28: pm_hmac_rx_data_process | I28: 2
C29: .wifislprxiram.32 | D29: pm_dream | E29: =I45 -> 344 | H29: ppRxFragmentProc | I29: 1024
C30: .wifislprxiram.33 | D30: pm_sleep | E30: =I46 -> 530 | H30: hal_clear_rx_beacon_pti | I30: 18
C31: .wifislprxiram.34 | D31: pm_check_state | E31: =I47 -> 72 | H31: hal_mac_rx_get_last_dscr | I31: 26
C32: .wifislprxiram.41 | D32: pm_beacon_monitor_timeout_process | E32: =I48 -> 66 | H32: hal_mac_rx_is_dscr_reload | I32: 12
... C38: .wifislprxiram.53 | D38: pm_on_beacon_rx | E38: =I54 -> 264 | H38: pm_get_tbtt_count | I38: 176
C39: .wifislpiram.5 | D39: pm_get_connectionless_status | E39: =I64 -> 44 | H39: pm_parse_beacon | I39: 570
C40: .wifislpiram.22 | D40: pm_enable_dream_timer | E40: =I65 -> 66 | H40: pm_save_tbtt_info | I40: 34
C41: .wifislpiram.24 | D41: pm_update_by_connectionless_status | E41: =I66 -> 344 | H41: pm_beacon_monitor_tbtt_start | I41: 190
C42: .wifislpiram.36 | D42: pm_handle_tbtt_interval | E42: =I67 -> 134 | H42: pm_beacon_monitor_tbtt_stop | I42: 18
C43: .wifislpiram.38 | D43: pm_update_next_tbtt | E43: =I68 -> 268 | H43: pm_enable_beacon_monitor_timer | I43: 116
C44: .wifislpiram.43 | D44: pm_connectionless_wake_interval_timeout_process | E44: =I69 -> 66 | H44: pm_disable_beacon_monitor_timer | I44: 60
C45: .wifislpiram.44 | D45: pm_connectionless_wake_window_timeout_process | E45: =I70 -> 102 | H45: pm_dream | I45: 344
...

Sheet .data
C1: 3FC87460
A2: WIFI_EVENT | B2: 4 | C2: ="0x"&DEC2HEX(HEX2DEC($C$1)+SUM(B$2:$B2)) -> 0x3FC87464
A3: esp_wifi::wifi::DATA_QUEUE_RX_AP | B3: 20 | C3: ="0x"&DEC2HEX(HEX2DEC($C$1)+SUM(B$2:$B3)) -> 0x3FC87478
A4: esp_wifi::wifi::DATA_QUEUE_RX_STA | B4: 20 | C4: ="0x"&DEC2HEX(HEX2DEC($C$1)+SUM(B$2:$B4)) -> 0x3FC8748C
A5: esp_wifi::preempt_builtin::timer::TIMER | B5: 16 | C5: ="0x"&DEC2HEX(HEX2DEC($C$1)+SUM(B$2:$B5)) -> 0x3FC8749C
A6: padding | B6: 4 | C6: ="0x"&DEC2HEX(HEX2DEC($C$1)+SUM(B$2:$B6)) -> 0x3FC874A0
A7: esp_wifi::wifi::internal::G_CONFIG | B7: 224 | C7: ="0x"&DEC2HEX(HEX2DEC($C$1)+SUM(B$2:$B7)) -> 0x3FC87580
A8: esp_wifi: g_wifi_feature_caps | B8: 8 | C8: ="0x"&DEC2HEX(HEX2DEC($C$1)+SUM(B$2:$B8)) -> 0x3FC87588
A9: esp_wifi::wifi::state::STA_STATE | B9: 4 | C9: ="0x"&DEC2HEX(HEX2DEC($C$1)+SUM(B$2:$B9)) -> 0x3FC8758C
A10: esp_wifi::wifi::state::AP_STATE | B10: 4 | C10: ="0x"&DEC2HEX(HEX2DEC($C$1)+SUM(B$2:$B10)) -> 0x3FC87590
A11: esp_hal_embassy::time_driver::DRIVER | B11: 32 | C11: ="0x"&DEC2HEX(HEX2DEC($C$1)+SUM(B$2:$B11)) -> 0x3FC875B0
C12: ="0x"&DEC2HEX(HEX2DEC($C$1)+SUM(B$2:$B12)) -> 0x3FC875B0
A13: esp_hal::timer..systimer..Alarm as esp_hal_embassy::TimeBase::timers::STATIC_TIMER_CELL | B13: 12 | C13: ="0x"&DEC2HEX(HEX2DEC($C$1)+SUM(B$2:$B13)) -> 0x3FC875BC
A14: esp_hal::soc::implementation::peripherals::UART as esp_hal::uart::Instance::parts::PERIPHERAL | B14: 20 | C14: ="0x"&DEC2HEX(HEX2DEC($C$1)+SUM(B$2:$B14)) -> 0x3FC875D0
C15: ="0x"&DEC2HEX(HEX2DEC($C$1)+SUM(B$2:$B15)) -> 0x3FC875D0
A16: libnet80211.a(ieee80211_api.o):(.data.WIFI_MESH_EVENT) | B16: 4 | C16: ="0x"&DEC2HEX(HEX2DEC($C$1)+SUM(B$2:$B16)) -> 0x3FC875D4
A17: libnet80211.a(ieee80211_api.o):(.data.g_wifi_event_mask) | B17: 4 | C17: ="0x"&DEC2HEX(HEX2DEC($C$1)+SUM(B$2:$B17)) -> 0x3FC875D8
A18: libnet80211.a(ieee80211_api.o):(.data.s_wifi_init_state) | B18: 4 | C18: ="0x"&DEC2HEX(HEX2DEC($C$1)+SUM(B$2:$B18)) -> 0x3FC875DC
A19: libnet80211.a(ieee80211_action.o):(.data.ba_recv_action) | B19: 12 | C19: ="0x"&DEC2HEX(HEX2DEC($C$1)+SUM(B$2:$B19)) -> 0x3FC875E8
A20: libnet80211.a(ieee80211_action.o):(.data.ba_send_action) | B20: 12 | C20: ="0x"&DEC2HEX(HEX2DEC($C$1)+SUM(B$2:$B20)) -> 0x3FC875F4
A21: libnet80211.a(ieee80211_action.o):(.data.ht_recv_action) | B21: 4 | C21: ="0x"&DEC2HEX(HEX2DEC($C$1)+SUM(B$2:$B21)) -> 0x3FC875F8
A22: libnet80211.a(ieee80211_action.o):(.data.ht_send_action) | B22: 4 | C22: ="0x"&DEC2HEX(HEX2DEC($C$1)+SUM(B$2:$B22)) -> 0x3FC875FC
A23: libnet80211.a(ieee80211_action.o):(.data.public_recv_action) | B23: 136 | C23: ="0x"&DEC2HEX(HEX2DEC($C$1)+SUM(B$2:$B23)) -> 0x3FC87684
A24: libnet80211.a(ieee80211_action.o):(.data.public_send_action) | B24: 136 | C24: ="0x"&DEC2HEX(HEX2DEC($C$1)+SUM(B$2:$B24)) -> 0x3FC8770C
A25: libnet80211.a(ieee80211_action.o):(.data.sa_query_recv_action) | B25: 8 | C25: ="0x"&DEC2HEX(HEX2DEC($C$1)+SUM(B$2:$B25)) -> 0x3FC87714
A26: libnet80211.a(ieee80211_action.o):(.data.sa_query_send_action) | B26: 8 | C26: ="0x"&DEC2HEX(HEX2DEC($C$1)+SUM(B$2:$B26)) -> 0x3FC8771C
A27: libnet80211.a(ieee80211_action.o):(.data.vendor_recv_action) | B27: 4 | C27: ="0x"&DEC2HEX(HEX2DEC($C$1)+SUM(B$2:$B27)) -> 0x3FC87720
... A55: padding | B55: 3 | C55: ="0x"&DEC2HEX(HEX2DEC($C$1)+SUM(B$2:$B55)) -> 0x3FC87A58
C56: ="0x"&DEC2HEX(HEX2DEC($C$1)+SUM(B$2:$B56)) -> 0x3FC87A58
A57: libphy.a(phy_init.o):(.data.phy_param) | B57: 832 | C57: ="0x"&DEC2HEX(HEX2DEC($C$1)+SUM(B$2:$B57)) -> 0x3FC87D98
A58: libphy.a(phy_analog_cal.o):(.data.wifi_ht20) | B58: 2 | C58: ="0x"&DEC2HEX(HEX2DEC($C$1)+SUM(B$2:$B58)) -> 0x3FC87D9A
A59: libphy.a(phy_analog_cal.o):(.data.wifi_ht40) | B59: 2 | C59: ="0x"&DEC2HEX(HEX2DEC($C$1)+SUM(B$2:$B59)) -> 0x3FC87D9C
A60: libpp.a(esf_buf.o):(.data.g_eb_list_desc) | B60: 220 | C60: ="0x"&DEC2HEX(HEX2DEC($C$1)+SUM(B$2:$B60)) -> 0x3FC87E78
A61: libpp.a(lmac.o):(.data.g_txop_queue_status) | B61: 3 | C61: ="0x"&DEC2HEX(HEX2DEC($C$1)+SUM(B$2:$B61)) -> 0x3FC87E7B
A62: padding | B62: 1 | C62: ="0x"&DEC2HEX(HEX2DEC($C$1)+SUM(B$2:$B62)) -> 0x3FC87E7C
C63: ="0x"&DEC2HEX(HEX2DEC($C$1)+SUM(B$2:$B63)) -> 0x3FC87E7C
A64: libpp.a(lmac.o):(.data.lmacConfMib) | B64: 48 | C64: ="0x"&DEC2HEX(HEX2DEC($C$1)+SUM(B$2:$B64)) -> 0x3FC87EAC
A65: libpp.a(pm.o):(.data.g_pm_cfg) | B65: 68 | C65: ="0x"&DEC2HEX(HEX2DEC($C$1)+SUM(B$2:$B65)) -> 0x3FC87EF0
A66: libpp.a(pp.o):(.data.TxRxCxt) | B66: 960 | C66: ="0x"&DEC2HEX(HEX2DEC($C$1)+SUM(B$2:$B66)) -> 0x3FC882B0
A67: libpp.a(pp_timer.o):(.data.g_pp_timer_info) | B67: 96 | C67: ="0x"&DEC2HEX(HEX2DEC($C$1)+SUM(B$2:$B67)) -> 0x3FC88310
...

Sheet .bss
C1: 3FC887e0
A2: libwpa_supplicant.a(esp_wpa_main.c.obj):(.sbss.wpa_cb) | B2: 4 | C2: ="0x"&DEC2HEX(HEX2DEC($C$1)+SUM(B$2:$B2)) -> 0x3FC887E4
A3: libwpa_supplicant.a(esp_wpa_main.c.obj):(.sbss.wifi_funcs) | B3: 4 | C3: ="0x"&DEC2HEX(HEX2DEC($C$1)+SUM(B$2:$B3)) -> 0x3FC887E8
A4: libwpa_supplicant.a(esp_wpa_main.c.obj):(.sbss.g_wpa_pmk_caching_disabled) | B4: 1 | C4: ="0x"&DEC2HEX(HEX2DEC($C$1)+SUM(B$2:$B4)) -> 0x3FC887E9
A5: padding | B5: 3 | C5: ="0x"&DEC2HEX(HEX2DEC($C$1)+SUM(B$2:$B5)) -> 0x3FC887EC
A6: libwpa_supplicant.a(eloop.c.obj):(.sbss.eloop_data_lock) | B6: 4 | C6: ="0x"&DEC2HEX(HEX2DEC($C$1)+SUM(B$2:$B6)) -> 0x3FC887F0
A7: libwpa_supplicant.a(esp_eap_client.c.obj):(.sbss.gEapSm) | B7: 4 | C7: ="0x"&DEC2HEX(HEX2DEC($C$1)+SUM(B$2:$B7)) -> 0x3FC887F4
A8: libwpa_supplicant.a(wpa_auth.c.obj):(.sbss.s_sm_valid_bitmap) | B8: 4 | C8: ="0x"&DEC2HEX(HEX2DEC($C$1)+SUM(B$2:$B8)) -> 0x3FC887F8
A9: libwpa_supplicant.a(esp_wps.c.obj):(.sbss.s_wps_sm_cb) | B9: 4 | C9: ="0x"&DEC2HEX(HEX2DEC($C$1)+SUM(B$2:$B9)) -> 0x3FC887FC
A10: libwpa_supplicant.a(esp_hostap.c.obj):(.sbss.global_hapd) | B10: 4 | C10: ="0x"&DEC2HEX(HEX2DEC($C$1)+SUM(B$2:$B10)) -> 0x3FC88800
C11: ="0x"&DEC2HEX(HEX2DEC($C$1)+SUM(B$2:$B11)) -> 0x3FC88800
A12: uart_udp_server::udp::server::POOL | B12: 848 | C12: ="0x"&DEC2HEX(HEX2DEC($C$1)+SUM(B$2:$B12)) -> 0x3FC88B50
A13: uart_udp_server::debug_pin::DEBUG_PIN | B13: 2 | C13: ="0x"&DEC2HEX(HEX2DEC($C$1)+SUM(B$2:$B13)) -> 0x3FC88B52
A14: padding | B14: 6 | C14: ="0x"&DEC2HEX(HEX2DEC($C$1)+SUM(B$2:$B14)) -> 0x3FC88B58
A15: uart_udp_server::uart::client::POOL | B15: 216 | C15: ="0x"&DEC2HEX(HEX2DEC($C$1)+SUM(B$2:$B15)) -> 0x3FC88C30
A16: uart_udp_server::__embassy_main::POOL | B16: 40 | C16: ="0x"&DEC2HEX(HEX2DEC($C$1)+SUM(B$2:$B16)) -> 0x3FC88C58
A17: uart_udp_server::run::POOL | B17: 56 | C17: ="0x"&DEC2HEX(HEX2DEC($C$1)+SUM(B$2:$B17)) -> 0x3FC88C90
A18: uart_udp_server::net_task::POOL | B18: 72 | C18: ="0x"&DEC2HEX(HEX2DEC($C$1)+SUM(B$2:$B18)) -> 0x3FC88CD8
A19: uart_udp_server::____embassy_main_task::closure::HEAP | B19: 98304 | C19: ="0x"&DEC2HEX(HEX2DEC($C$1)+SUM(B$2:$B19)) -> 0x3FCA0CD8
A20: uart_udp_server::____embassy_main_task::closure::STATIC_CELL | B20: 1 | C20: ="0x"&DEC2HEX(HEX2DEC($C$1)+SUM(B$2:$B20)) -> 0x3FCA0CD9
A21: padding | B21: 7 | C21: ="0x"&DEC2HEX(HEX2DEC($C$1)+SUM(B$2:$B21)) -> 0x3FCA0CE0
A22: uart_udp_server::____embassy_main_task::closure::STATIC_CELL | B22: 776 | C22: ="0x"&DEC2HEX(HEX2DEC($C$1)+SUM(B$2:$B22)) -> 0x3FCA0FE8
A23: uart_udp_server::____embassy_main_task::closure::STATIC_CELL | B23: 68 | C23: ="0x"&DEC2HEX(HEX2DEC($C$1)+SUM(B$2:$B23)) -> 0x3FCA102C
... A25: uart_udp_server::____embassy_main_task::closure::STATIC_CELL | B25: 68 | C25: ="0x"&DEC2HEX(HEX2DEC($C$1)+SUM(B$2:$B25)) -> 0x3FCA109C
A26: uart_udp_server::____embassy_main_task::closure::STATIC_CELL | B26: 44
A27: __rust_no_alloc_shim_is_unstable | B27: 1 | C27: ="0x"&DEC2HEX(HEX2DEC($C$1)+SUM(B$2:$B27)) -> 0x3FCA10C9
A28: esp_wifi::common_adapter::chip_specific::SOC_PHY_DIG_REGS_MEM | B28: 84 | C28: ="0x"&DEC2HEX(HEX2DEC($C$1)+SUM(B$2:$B28)) -> 0x3FCA111D
A29: padding | B29: 3 | C29: ="0x"&DEC2HEX(HEX2DEC($C$1)+SUM(B$2:$B29)) -> 0x3FCA1120
A30: esp_wifi::preempt_builtin::SCHEDULER_STATE | B30: 12 | C30: ="0x"&DEC2HEX(HEX2DEC($C$1)+SUM(B$2:$B30)) -> 0x3FCA112C
A31: esp_wifi::wifi::os_adapter::WIFI_LOCK | B31: 1 | C31: ="0x"&DEC2HEX(HEX2DEC($C$1)+SUM(B$2:$B31)) -> 0x3FCA112D
A32: padding | B32: 3 | C32: ="0x"&DEC2HEX(HEX2DEC($C$1)+SUM(B$2:$B32)) -> 0x3FCA1130
A33: esp_wifi::wifi::os_adapter::QUEUE_HANDLE | B33: 4 | C33: ="0x"&DEC2HEX(HEX2DEC($C$1)+SUM(B$2:$B33)) -> 0x3FCA1134
A34: esp_wifi::common_adapter::chip_specific::G_PHY_DIGITAL_REGS_MEM | B34: 4 | C34: ="0x"&DEC2HEX(HEX2DEC($C$1)+SUM(B$2:$B34)) -> 0x3FCA1138
A35: esp_wifi::wifi::embassy::STA_RECEIVE_WAKER | B35: 12 | C35: ="0x"&DEC2HEX(HEX2DEC($C$1)+SUM(B$2:$B35)) -> 0x3FCA1144
A36: esp_wifi::wifi::embassy::AP_RECEIVE_WAKER | B36: 12 | C36: ="0x"&DEC2HEX(HEX2DEC($C$1)+SUM(B$2:$B36)) -> 0x3FCA1150
A37: esp_wifi::wifi::embassy::TRANSMIT_WAKER | B37: 12 | C37: ="0x"&DEC2HEX(HEX2DEC($C$1)+SUM(B$2:$B37)) -> 0x3FCA115C
A38: esp_wifi::wifi::os_adapter::ISR_INTERRUPT_1 | B38: 8 | C38: ="0x"&DEC2HEX(HEX2DEC($C$1)+SUM(B$2:$B38)) -> 0x3FCA1164
... A77: console::jtag_serial::TIMED_OUT | B77: 1 | C77: ="0x"&DEC2HEX(HEX2DEC($C$1)+SUM(B$2:$B77)) -> 0x3FCA1896
C78: ="0x"&DEC2HEX(HEX2DEC($C$1)+SUM(B$2:$B78)) -> 0x3FCA1896
A79: libnet80211.a(ieee80211_api.o):(.bss.s_net80211_data_init) | B79: 1 | C79: ="0x"&DEC2HEX(HEX2DEC($C$1)+SUM(B$2:$B79)) -> 0x3FCA1897
...

Sheet .rodata
C1: 3C000020
A2: embassy_executor::raw::TaskStorage::poll | B2: 32 | C2: ="0x"&DEC2HEX(HEX2DEC(C$1)+SUM($B$2:B2)) -> 0x3C000040
A3: embassy_executor::raw::TaskStorage::poll | B3: 28 | C3: ="0x"&DEC2HEX(HEX2DEC(C$1)+SUM($B$2:B3)) -> 0x3C00005C
A4: .Lanon | B4: 208 | C4: ="0x"&DEC2HEX(HEX2DEC(C$1)+SUM($B$2:B4)) -> 0x3C00012C
A5: esp_wifi::wifi::embassy imp embassy_net_driver::TxToken for esp_wifi::wifi::WifiTxToken::consume | B5: 52 | C5: ="0x"&DEC2HEX(HEX2DEC(C$1)+SUM($B$2:B5)) -> 0x3C000160
A6: .Lanon | B6: 304 | C6: ="0x"&DEC2HEX(HEX2DEC(C$1)+SUM($B$2:B6)) -> 0x3C000290
A7: anon | B7: 92 | C7: ="0x"&DEC2HEX(HEX2DEC(C$1)+SUM($B$2:B7)) -> 0x3C0002EC
A8: .Lanon | B8: 3 | C8: ="0x"&DEC2HEX(HEX2DEC(C$1)+SUM($B$2:B8)) -> 0x3C0002EF
A9: anon | B9: 101 | C9: ="0x"&DEC2HEX(HEX2DEC(C$1)+SUM($B$2:B9)) -> 0x3C000354
A10: .Lanon | B10: 84 | C10: ="0x"&DEC2HEX(HEX2DEC(C$1)+SUM($B$2:B10)) -> 0x3C0003A8
A11: anon | B11: 344 | C11: ="0x"&DEC2HEX(HEX2DEC(C$1)+SUM($B$2:B11)) -> 0x3C000500
A12: .Lanon | B12: 76 | C12: ="0x"&DEC2HEX(HEX2DEC(C$1)+SUM($B$2:B12)) -> 0x3C00054C
A13: anon | B13: 180 | C13: ="0x"&DEC2HEX(HEX2DEC(C$1)+SUM($B$2:B13)) -> 0x3C000600
... A98: libwpa_supplicant.a(sha1-internal.c.obj):(.srodata.memset_func) | B98: 4 | C98: ="0x"&DEC2HEX(HEX2DEC(C$1)+SUM($B$2:B98)) -> 0x3C0035C4
A99: libwpa_supplicant.a(sha1.c.obj):(.srodata.memset_func) | B99: 4 | C99: ="0x"&DEC2HEX(HEX2DEC(C$1)+SUM($B$2:B99)) -> 0x3C0035C8 | D99: =SUM(B$2:$B100) -> 13736 | E99: ="0x"&DEC2HEX(D99) -> 0x35A8

Sheet .esp-hal
A1: _setup_interrupts | B1: 718
A2: esp_hal::interrupt::riscv::vectored::enable | B2: 52
A3: hal_main | B3: 8
A4: esp_hal::init | B4: 398
A5: EspDefaultHandler | B5: 2
A6: _critical_section_1_0_acquire | B6: 10
A7: _critical_section_1_0_release | B7: 12
A9: esp_hal::clock::Clocks::get | B9: 22
A10: esp_hal::clock::clocks_ll::esp32c3_rtc_bbpll_configure | B10: 390
A11: esp_hal::clock::clocks_ll::enable_phy | B11: 36
A12: esp_hal::clock::clocks_ll::reset_mac | B12: 20
A13: esp_hal::clock::clocks_ll::init_clocks | B13: 62
... A20: esp_hal::timer::OneShotTimer::stop | B20: 50
A21: esp_hal::timer::PeriodicTimer::set_interrupt_handler
A22: esp_hal::timer::OneShotTimer::set_interrupt_handler | B22: 116
A23: esp_hal::timer::PeriodicTime::::enable_interrupt
A24: esp_hal::timer::OneShotTimer::enable_interrupt | B24: 58
A25: esp_hal::timer::PeriodicTime::clear_interrupt
A26: esp_hal::timer::OneShotTimer::clear_interrupt | B26: 64
A27: esp_hal::timer::PeriodicTimer::start | B27: 510
A29: esp_hal::soc::implementation::peripherals::TIMG0 as
A30: esp_hal::timer::timg::TimerGroupInstance::configure_src_clk | B30: 14
A31: esp_hal::soc::implementation::peripherals::TIMG0 as
A32: esp_hal::timer::timg::TimerGroupInstance::enable_peripheral | B32: 44
A33: esp_hal::soc::implementation::peripherals::TIMG0 as
A34: esp_hal::timer::timg::TimerGroupInstance::configure_wdt_src_clk | B34: 18
A36: esp_hal::uart::UartBuilder::init | B36: 822
A37: esp_hal::uart::UartTx::flush_last_byte | B37: 36
A38: esp_hal::uart::UartRx::apply_config | B38: 222
A39: esp_hal::uart::Uart::apply_config | B39: 440
A40: esp_hal::uart::Uart::set_at_cmd | B40: 110
A41: esp_hal::uart::Uart::with_tx | B41: 306
A42: esp_hal::uart::rx_event_check_for_error | B42: 100
A43: esp_hal::uart::Info::set_rx_fifo_full_threshold | B43: 28
A44: esp_hal::uart::Info::rx_fifo_full_threshold | B44: 10
A45: esp_hal::uart::Info::rxfifo_reset | B45: 68
A46: esp_hal::uart::Info::tx_fifo_count | B46: 10
... A57: esp_hal::gpio::PinGuard as core::ops::drop::Drop | B57: 60
A58: esp_hal::gpio::interconnect::InputSignal
A59: as esp_hal::gpio::interconnect::PeripheralSignal::connect_input_to_peripheral
...

Sheet embassy
A1: .embassy
B2: embassy_executor::raw::poll_exited | C2: 2
B4: // these are the two tasks (put into .main)
B5: //embassy_executor::raw::TaskStorage::poll
B6: //embassy_executor::raw::TaskStorage::poll
B8: embassy_executor::raw::util::UninitCell::write_in_place | C8: 18
B9: embassy_executor::raw::util::UninitCell::write_in_place | C9: 22
B10: embassy_executor::raw::util::UninitCell::write_in_place | C10: 12
B11: embassy_executor::raw::util::UninitCell::write_in_place | C11: 8
B12: embassy_executor::raw::util::UninitCell::write_in_place | C12: 6
B14: embassy_executor::raw::waker::clone | C14: 16
B15: embassy_executor::raw::waker::wake | C15: 84
B16: embassy_executor::raw::waker::drop | C16: 2
B17: embassy_executor::raw::waker::task_from_waker | C17: 20
B19: embassy_executor::raw::Executor::poll | C19: 60
B20: embassy_executor::raw::wake_task | C20: 84
B21: embassy_executor::spawner::Spawner::spawn | C21: 70
... B40: embassy_futures::select::Select as core::future::future::Future::poll | C40: 730
B42: core::ptr::drop_in_place core::result::Result
B43: embassy_sync::zerocopy_channel::Channel
B44: embassy_sync::blocking_mutex::raw::NoopRawMutex
B45: uart_udp_server::ChannelItem | C45: 46
B47: embassy_sync::waitqueue::waker_registration::WakerRegistration::register | C47: 86
B48: embassy_sync::waitqueue::waker_registration::WakerRegistration::wake | C48: 18
B49: embassy_sync::zerocopy_channel::State::push_done | C49: 56
B50: embassy_sync::zerocopy_channel::State::pop_done | C50: 58 | D50: =SUM($B$1:C50) -> 5128 | E50: ="0x"&DEC2HEX(D50) -> 0x1408
A53: .esp_embassy
B54: esp_hal_embassy::Executor::run | C54: 88
B55: esp_hal_embassy::Executor::wait_impl | C55: 42
B56: esp_hal_embassy::time_driver::EmbassyTimer::init | C56: 96
B57: esp_hal_embassy::time_driver::DRIVER::handler | C57: 54
B58: esp_hal_embassy::timer_queue::TimerQueue::dispatch | C58: 480 | D58: =SUM($B$54:C58) -> 760 | E58: ="0x"&DEC2HEX(D58) -> 0x2F8

Sheet alloc+atomic
A1: .esp_alloc
B2: esp_alloc::EspHeap::init | C2: 142
B3: esp_alloc::EspHeap as core::alloc::global::GlobalAlloc::alloc | C3: 112
B4: esp_alloc::EspHeap as core::alloc::global::GlobalAlloc::dealloc | C4: 150
B6: ___rustc12___rust_alloc | C6: 138
B7: ___rustc14___rust_dealloc | C7: 182
B8: ___rustc14___rust_realloc | C8: 308
B9: ___rustc19___rust_alloc_zeroed | C9: 168
B11: linked_list_allocator::hole::HoleList::allocate_first_fit | C11: 248
B12: linked_list_allocator::hole::HoleList::deallocate | C12: 292
B13: linked_list_allocator::Heap::init | C13: 52
B14: linked_list_allocator::Heap::allocate_first_fit | C14: 48
B15: linked_list_allocator::Heap::deallocate | C15: 32
B17: allocator_api::raw_vec::capacity_overflow | C17: 2
B18: allocator_api::vec::Vec::swap_remove::assert_failed | C18: 2 | D18: =SUM($C2:C$18) -> 1876 | E18: ="0x"&DEC2HEX(D18) -> 0x754
A21: .port_atomic
B22: portable_atomic::AtomicBool::load | C22: 72
B23: portable_atomic::AtomicUsize::load
B24: portable_atomic::AtomicU32::load | C24: 42
B25: portable_atomic::AtomicUsize::store
B26: portable_atomic::AtomicU32::store | C26: 42 | D26: =SUM($C22:C$26) -> 156 | E26: ="0x"&DEC2HEX(D26) -> 0x9C

Sheet .esp-wifi
A1: esp_wifi::init_clocks | B1: 8
A3: esp_wifi::common_adapter::semphr_create | B3: 50
A5: esp_wifi::wifi::os_adapter:spin_lock_delete
A6: esp_wifi::common_adapter::semphr_delete
A7: esp_wifi::wifi::os_adapter::mutex_delete | B7: 30
A8: esp_wifi::common_adapter::read_mac | B8: 138
A9: esp_wifi::common_adapter::chip_specific::enable_wifi_power_domain | B9: 64
A11: puts | B11: 2
A12: ets_timer_disarm | B12: 104
A13: ets_timer_setfn | B13: 52
A15: esp_wifi::compat::common::lock_mutex | B15: 172
A16: esp_wifi::compat::common::sem_take | B16: 310
A17: esp_wifi::compat::common::receive_queued | B17: 248
A18: strnlen | B18: 20
A20: strrchr | B20: 2
A21: sleep | B21: 28
... A32: esp_wifi::preempt::enable | B32: 8
A33: esp_wifi::preempt_builtin::timer::arch_specific::yield_task
A34: esp_wifi::preempt::yield_task | B34: 14
A35: esp_wifi::5preempt_builtin::timer::timer_tick_handler | B35: 180
A36: esp_wifi::preempt_builtin::timer::arch_specific::setup_timer | B36: 192
A37: FROM_CPU_INTR2 | B37: 108
A38: esp_wifi::preempt_builtin::SchedulerState::switch_task | B38: 368
A39: esp_wifi::preempt_builtin::BuiltinScheduler as
A40: esp_wifi::preempt::Scheduler::task_create | B40: 326
A42: esp_wifi::tasks::init_tasks | B42: 20
A43: esp_wifi::tasks::timer_task | B43: 296
A45: esp_wifi::wifi::new | B45: 428
A46: esp_wifi::wifi::esp_wifi_send_data | B46: 98
A48: esp_wifi::wifi::os_adapter::spin_lock_create | B48: 46
A49: esp_wifi::wifi::os_adapter::wifi_int_disable | B49: 16
A50: esp_wifi::wifi::os_adapter::wifi_int_restore | B50: 16
A51: esp_wifi_preempt_current_task_thread_semaphore
A52: esp_wifi::wifi::os_adapter::wifi_thread_semphr_get | B52: 78
A53: esp_wifi::wifi::os_adapter::recursive_mutex_create | B53: 58
A54: esp_wifi::wifi::os_adapter::mutex_lock | B54: 8
A55: esp_wifi::wifi::os_adapter::mutex_unlock | B55: 66
A56: esp_wifi::wifi::os_adapter::queue_send | B56: 26
A57: esp_wifi::wifi::os_adapter::queue_send_from_isr | B57: 34
A58: esp_wifi::wifi::os_adapter::queue_recv | B58: 8
...

Sheet libcore printf
A1: .libcore
B2: misc_nvs_load | C2: 164
B3: misc_nvs_deinit | C3: 92
B4: misc_nvs_init | C4: 48
B5: mesh_sta_auth_expire_time | C5: 64 | D5: =SUM($B$1:C5) -> 368 | E5: ="0x"&DEC2HEX(D5) -> 0x170
A8: .libprintf
B9: _out_buffer | C9: 12
B10: _out_null | C10: 2
B11: _out_rev | C11: 180
B12: _ntoa_format | C12: 332
B13: _ntoa_long | C13: 132
B14: _ntoa_long_long | C14: 240
B15: _etoa | C15: 1168
B16: _ftoa | C16: 1028
B17: _vsnprintf | C17: 1508
B18: sprintf | C18: 42 | D18: =SUM($B$9:C18) -> 4644 | E18: ="0x"&DEC2HEX(D18) -> 0x1224

Sheet .libpp
A1: esf_buf.o | D1: 42016910
B2: esf_buf_alloc_dynamic_default_handler | C2: 34 | D2: ="0x"&DEC2HEX(HEX2DEC(D$1)+SUM($C$2:C2)) -> 0x42016932
B3: esf_buf_alloc_default_handler | C3: 34 | D3: ="0x"&DEC2HEX(HEX2DEC(D$1)+SUM($C$2:C3)) -> 0x42016954
B4: esf_buf_recycle_default_handler | C4: 34 | D4: ="0x"&DEC2HEX(HEX2DEC(D$1)+SUM($C$2:C4)) -> 0x42016976
B5: esf_buf_setup_static | C5: 110 | D5: ="0x"&DEC2HEX(HEX2DEC(D$1)+SUM($C$2:C5)) -> 0x420169E4
B6: esf_buf_free_static | C6: 182 | D6: ="0x"&DEC2HEX(HEX2DEC(D$1)+SUM($C$2:C6)) -> 0x42016A9A
B7: esf_buf_setdown | C7: 32 | D7: ="0x"&DEC2HEX(HEX2DEC(D$1)+SUM($C$2:C7)) -> 0x42016ABA
B8: esf_buf_setup | C8: 504 | D8: ="0x"&DEC2HEX(HEX2DEC(D$1)+SUM($C$2:C8)) -> 0x42016CB2
A9: if_hecfg.o
A10: if_hwctrl.o
B11: ic_get_addr | C11: 18 | D11: ="0x"&DEC2HEX(HEX2DEC(D$1)+SUM($C$2:C11)) -> 0x42016CC4
B12: ic_get_ptk_alg | C12: 22 | D12: ="0x"&DEC2HEX(HEX2DEC(D$1)+SUM($C$2:C12)) -> 0x42016CDA
B13: ic_disable_crypto | C13: 28 | D13: ="0x"&DEC2HEX(HEX2DEC(D$1)+SUM($C$2:C13)) -> 0x42016CF6
B14: ic_set_key | C14: 64 | D14: ="0x"&DEC2HEX(HEX2DEC(D$1)+SUM($C$2:C14)) -> 0x42016D36
B15: ic_get_key | C15: 94 | D15: ="0x"&DEC2HEX(HEX2DEC(D$1)+SUM($C$2:C15)) -> 0x42016D94
B16: ic_obtain_key | C16: 132 | D16: ="0x"&DEC2HEX(HEX2DEC(D$1)+SUM($C$2:C16)) -> 0x42016E18
B17: ic_tx_pkt | C17: 10 | D17: ="0x"&DEC2HEX(HEX2DEC(D$1)+SUM($C$2:C17)) -> 0x42016E22
B18: ic_register_tx_cb | C18: 4 | D18: ="0x"&DEC2HEX(HEX2DEC(D$1)+SUM($C$2:C18)) -> 0x42016E26
B19: ic_register_rx_cb | C19: 4 | D19: ="0x"&DEC2HEX(HEX2DEC(D$1)+SUM($C$2:C19)) -> 0x42016E2A
B20: ic_register_timer_post_cb | C20: 4 | D20: ="0x"&DEC2HEX(HEX2DEC(D$1)+SUM($C$2:C20)) -> 0x42016E2E
B21: ic_register_michael_mic_failure_cb | C21: 4 | D21: ="0x"&DEC2HEX(HEX2DEC(D$1)+SUM($C$2:C21)) -> 0x42016E32
B22: ic_register_pp_tx_done_cb | C22: 4 | D22: ="0x"&DEC2HEX(HEX2DEC(D$1)+SUM($C$2:C22)) -> 0x42016E36
... B65: ic_get_default_sched | C65: 4 | D65: ="0x"&DEC2HEX(HEX2DEC(D$1)+SUM($C$2:C65)) -> 0x42017392
A66: lmac.o
B67: lmacGetTxFrame | C67: 32 | D67: ="0x"&DEC2HEX(HEX2DEC(D$1)+SUM($C$2:C67)) -> 0x420173B2
B68: lmacSetAcParam | C68: 68 | D68: ="0x"&DEC2HEX(HEX2DEC(D$1)+SUM($C$2:C68)) -> 0x420173F6
B69: lmacInitAc | C69: 72 | D69: ="0x"&DEC2HEX(HEX2DEC(D$1)+SUM($C$2:C69)) -> 0x4201743E
B70: lmacInit | C70: 156 | D70: ="0x"&DEC2HEX(HEX2DEC(D$1)+SUM($C$2:C70)) -> 0x420174DA
B71: lmacEndRetryAMPDUFail | C71: 136 | D71: ="0x"&DEC2HEX(HEX2DEC(D$1)+SUM($C$2:C71)) -> 0x42017562
B72: lmacDebugTxDrop | D72: ="0x"&DEC2HEX(HEX2DEC(D$1)+SUM($C$2:C72)) -> 0x42017562
B73: dbg_cnt_lmac_drop | C73: 150 | D73: ="0x"&DEC2HEX(HEX2DEC(D$1)+SUM($C$2:C73)) -> 0x420175F8
B74: lmac_record_txtime | C74: 304 | D74: ="0x"&DEC2HEX(HEX2DEC(D$1)+SUM($C$2:C74)) -> 0x42017728
B75: lmac_update_tx_statistic | C75: 2 | D75: ="0x"&DEC2HEX(HEX2DEC(D$1)+SUM($C$2:C75)) -> 0x4201772A
B76: lmacDiscardMSDU | C76: 186 | D76: ="0x"&DEC2HEX(HEX2DEC(D$1)+SUM($C$2:C76)) -> 0x420177E4
B77: lmacRetryTxFrame | C77: 230 | D77: ="0x"&DEC2HEX(HEX2DEC(D$1)+SUM($C$2:C77)) -> 0x420178CA
B78: lmacProcessTxopQComplete | C78: 380 | D78: ="0x"&DEC2HEX(HEX2DEC(D$1)+SUM($C$2:C78)) -> 0x42017A46
B79: lmacProcessShortRetryFail | C79: 638 | D79: ="0x"&DEC2HEX(HEX2DEC(D$1)+SUM($C$2:C79)) -> 0x42017CC4
B80: lmacProcessCtsTimeout | C80: 112 | D80: ="0x"&DEC2HEX(HEX2DEC(D$1)+SUM($C$2:C80)) -> 0x42017D34
B81: lmacProcessLongRetryFail | C81: 478 | D81: ="0x"&DEC2HEX(HEX2DEC(D$1)+SUM($C$2:C81)) -> 0x42017F12
B82: lmacProcessCollision | C82: 226 | D82: ="0x"&DEC2HEX(HEX2DEC(D$1)+SUM($C$2:C82)) -> 0x42017FF4
...

Sheet .libphy
A1: phy_analog_cal.o | D1: 4201f6a4
B2: get_rc_dout | C2: 308 | D2: ="0x"&DEC2HEX(HEX2DEC(D$1)+SUM($C$2:C2)) -> 0x4201F7D8
B3: rc_cal | C3: 426 | D3: ="0x"&DEC2HEX(HEX2DEC(D$1)+SUM($C$2:C3)) -> 0x4201F982
A4: phy_api.o
B5: phy_change_channel | C5: 18 | D5: ="0x"&DEC2HEX(HEX2DEC(D$1)+SUM($C$2:C5)) -> 0x4201F994
B6: phy_bbpll_en_usb | C6: 10 | D6: ="0x"&DEC2HEX(HEX2DEC(D$1)+SUM($C$2:C6)) -> 0x4201F99E
B7: phy_get_rf_cal_version | C7: 6 | D7: ="0x"&DEC2HEX(HEX2DEC(D$1)+SUM($C$2:C7)) -> 0x4201F9A4
B8: noise_check_loop | C8: 2 | D8: ="0x"&DEC2HEX(HEX2DEC(D$1)+SUM($C$2:C8)) -> 0x4201F9A6
A9: phy_basic.o
B10: chan14_mic_cfg | C10: 64 | D10: ="0x"&DEC2HEX(HEX2DEC(D$1)+SUM($C$2:C10)) -> 0x4201F9E6
A11: phy_debug.o
B12: get_phy_version_str | C12: 66 | D12: ="0x"&DEC2HEX(HEX2DEC(D$1)+SUM($C$2:C12)) -> 0x4201FA28
B13: get_iq_value | C13: 68 | D13: ="0x"&DEC2HEX(HEX2DEC(D$1)+SUM($C$2:C13)) -> 0x4201FA6C
B14: get_bias_ref_code | C14: 134 | D14: ="0x"&DEC2HEX(HEX2DEC(D$1)+SUM($C$2:C14)) -> 0x4201FAF2
B15: phy_get_vdd33 | C15: 168 | D15: ="0x"&DEC2HEX(HEX2DEC(D$1)+SUM($C$2:C15)) -> 0x4201FB9A
A16: phy_feature.o
B17: phy_set_most_tpw | C17: 22 | D17: ="0x"&DEC2HEX(HEX2DEC(D$1)+SUM($C$2:C17)) -> 0x4201FBB0
B18: phy_11p_set | C18: 470 | D18: ="0x"&DEC2HEX(HEX2DEC(D$1)+SUM($C$2:C18)) -> 0x4201FD86
B19: phy_enable_low_rate | C19: 44 | D19: ="0x"&DEC2HEX(HEX2DEC(D$1)+SUM($C$2:C19)) -> 0x4201FDB2
B20: phy_disable_low_rate | C20: 44 | D20: ="0x"&DEC2HEX(HEX2DEC(D$1)+SUM($C$2:C20)) -> 0x4201FDDE
B21: set_rx_sense | C21: 554 | D21: ="0x"&DEC2HEX(HEX2DEC(D$1)+SUM($C$2:C21)) -> 0x42020008
A22: phy_hw_freq.o
B23: wr_rf_freq_mem | C23: 86 | D23: ="0x"&DEC2HEX(HEX2DEC(D$1)+SUM($C$2:C23)) -> 0x4202005E
B24: freq_i2c_write_set | C24: 1328 | D24: ="0x"&DEC2HEX(HEX2DEC(D$1)+SUM($C$2:C24)) -> 0x4202058E
B25: get_rf_freq_init | C25: 400 | D25: ="0x"&DEC2HEX(HEX2DEC(D$1)+SUM($C$2:C25)) -> 0x4202071E
B26: freq_get_i2c_data | C26: 566 | D26: ="0x"&DEC2HEX(HEX2DEC(D$1)+SUM($C$2:C26)) -> 0x42020954
B27: freq_i2c_data_write | C27: 60 | D27: ="0x"&DEC2HEX(HEX2DEC(D$1)+SUM($C$2:C27)) -> 0x42020990
B28: set_chan_freq_hw_init | C28: 158 | D28: ="0x"&DEC2HEX(HEX2DEC(D$1)+SUM($C$2:C28)) -> 0x42020A2E
B29: set_chan_freq_sw_start | C29: 186 | D29: ="0x"&DEC2HEX(HEX2DEC(D$1)+SUM($C$2:C29)) -> 0x42020AE8
A30: phy_i2c.o
B31: rom_i2c_sar2_init_code | C31: 70 | D31: ="0x"&DEC2HEX(HEX2DEC(D$1)+SUM($C$2:C31)) -> 0x42020B2E
B32: phy_i2c_init2 | C32: 850 | D32: ="0x"&DEC2HEX(HEX2DEC(D$1)+SUM($C$2:C32)) -> 0x42020E80
B33: phy_get_i2c_data | C33: 78 | D33: ="0x"&DEC2HEX(HEX2DEC(D$1)+SUM($C$2:C33)) -> 0x42020ECE
B34: bias_reg_set | C34: 152 | D34: ="0x"&DEC2HEX(HEX2DEC(D$1)+SUM($C$2:C34)) -> 0x42020F66
B35: i2c_bbpll_set | C35: 252 | D35: ="0x"&DEC2HEX(HEX2DEC(D$1)+SUM($C$2:C35)) -> 0x42021062
A36: phy_init.o
B37: phy_get_romfunc_addr | C37: 518 | D37: ="0x"&DEC2HEX(HEX2DEC(D$1)+SUM($C$2:C37)) -> 0x42021268
B38: rf_init | C38: 224 | D38: ="0x"&DEC2HEX(HEX2DEC(D$1)+SUM($C$2:C38)) -> 0x42021348
B39: register_chipv7_phy_init_param | C39: 306 | D39: ="0x"&DEC2HEX(HEX2DEC(D$1)+SUM($C$2:C39)) -> 0x4202147A
B40: phy_set_mac_data | C40: 28 | D40: ="0x"&DEC2HEX(HEX2DEC(D$1)+SUM($C$2:C40)) -> 0x42021496
...

Sheet .libnet80211
A1: ieee80211_action.o | D1: 42027978
B2: send_inval | C2: 4 | D2: ="0x"&DEC2HEX(HEX2DEC(D$1)+SUM($C$2:C2)) -> 0x4202797C
B3: recv_inval | C3: 4 | D3: ="0x"&DEC2HEX(HEX2DEC(D$1)+SUM($C$2:C3)) -> 0x42027980
B4: ieee80211_send_action_register | C4: 128 | D4: ="0x"&DEC2HEX(HEX2DEC(D$1)+SUM($C$2:C4)) -> 0x42027A00
B5: ieee80211_send_action | C5: 150 | D5: ="0x"&DEC2HEX(HEX2DEC(D$1)+SUM($C$2:C5)) -> 0x42027A96
B6: ieee80211_recv_action_register | C6: 128 | D6: ="0x"&DEC2HEX(HEX2DEC(D$1)+SUM($C$2:C6)) -> 0x42027B16
B7: ieee80211_recv_action | C7: 204 | D7: ="0x"&DEC2HEX(HEX2DEC(D$1)+SUM($C$2:C7)) -> 0x42027BE2
A8: ieee80211_action_vendor.o | D8: ="0x"&DEC2HEX(HEX2DEC(D$1)+SUM($C$2:C8)) -> 0x42027BE2
B9: get_iav_key | C9: 20 | D9: ="0x"&DEC2HEX(HEX2DEC(D$1)+SUM($C$2:C9)) -> 0x42027BF6
B10: ieee80211_recv_action_vendor_spec | C10: 274 | D10: ="0x"&DEC2HEX(HEX2DEC(D$1)+SUM($C$2:C10)) -> 0x42027D08
B11: ieee80211_action_vendor_spec_attach | C11: 46 | D11: ="0x"&DEC2HEX(HEX2DEC(D$1)+SUM($C$2:C11)) -> 0x42027D36
A12: ieee80211_api.o
B13: wifi_ant_update_empty_func | C13: 4 | D13: ="0x"&DEC2HEX(HEX2DEC(D$1)+SUM($C$2:C13)) -> 0x42027D3A
B14: esp_wifi_set_inactive_time_local | C14: 118 | D14: ="0x"&DEC2HEX(HEX2DEC(D$1)+SUM($C$2:C14)) -> 0x42027DB0
B15: esp_wifi_send_deauth_local | C15: 20 | D15: ="0x"&DEC2HEX(HEX2DEC(D$1)+SUM($C$2:C15)) -> 0x42027DC4
B16: wifi_get_init_state | C16: 10 | D16: ="0x"&DEC2HEX(HEX2DEC(D$1)+SUM($C$2:C16)) -> 0x42027DCE
B17: wifi_is_stop_in_progress | C17: 10 | D17: ="0x"&DEC2HEX(HEX2DEC(D$1)+SUM($C$2:C17)) -> 0x42027DD8
B18: wifi_api_lock | C18: 88 | D18: ="0x"&DEC2HEX(HEX2DEC(D$1)+SUM($C$2:C18)) -> 0x42027E30
B19: wifi_api_unlock | C19: 40 | D19: ="0x"&DEC2HEX(HEX2DEC(D$1)+SUM($C$2:C19)) -> 0x42027E58
B20: wifi_init_completed | C20: 42 | D20: ="0x"&DEC2HEX(HEX2DEC(D$1)+SUM($C$2:C20)) -> 0x42027E82
B21: wifi_station_get_config_local | C21: 414 | D21: ="0x"&DEC2HEX(HEX2DEC(D$1)+SUM($C$2:C21)) -> 0x42028020
B22: wifi_softap_get_config | C22: 390 | D22: ="0x"&DEC2HEX(HEX2DEC(D$1)+SUM($C$2:C22)) -> 0x420281A6
B23: esp_wifi_get_mode | C23: 52 | D23: ="0x"&DEC2HEX(HEX2DEC(D$1)+SUM($C$2:C23)) -> 0x420281DA
B24: wifi_deinit_in_caller_task | C24: 54 | D24: ="0x"&DEC2HEX(HEX2DEC(D$1)+SUM($C$2:C24)) -> 0x42028210
... B48: esp_mesh_get_running_active_duty_cycle | C48: 76 | D48: ="0x"&DEC2HEX(HEX2DEC(D$1)+SUM($C$2:C48)) -> 0x42028DDC
A49: ieee80211_btwt.o
A50: ieee80211.o
B51: ieee80211_freedom_inside_cb | C51: 42 | D51: ="0x"&DEC2HEX(HEX2DEC(D$1)+SUM($C$2:C51)) -> 0x42028E06
B52: ieee80211_send_sa_query | C52: 200 | D52: ="0x"&DEC2HEX(HEX2DEC(D$1)+SUM($C$2:C52)) -> 0x42028ECE
B53: ieee80211_send_sa_query_resp | C53: 24 | D53: ="0x"&DEC2HEX(HEX2DEC(D$1)+SUM($C$2:C53)) -> 0x42028EE6
B54: ieee80211_send_sa_query_req | C54: 24 | D54: ="0x"&DEC2HEX(HEX2DEC(D$1)+SUM($C$2:C54)) -> 0x42028EFE
B55: ieee80211_recv_sa_query_resp | C55: 232 | D55: ="0x"&DEC2HEX(HEX2DEC(D$1)+SUM($C$2:C55)) -> 0x42028FE6
B56: ieee80211_recv_sa_query_req | C56: 28 | D56: ="0x"&DEC2HEX(HEX2DEC(D$1)+SUM($C$2:C56)) -> 0x42029002
B57: ieee80211_rate_ref_init | C57: 24 | D57: ="0x"&DEC2HEX(HEX2DEC(D$1)+SUM($C$2:C57)) -> 0x4202901A
B58: ieee80211_freedom_init | C58: 34 | D58: ="0x"&DEC2HEX(HEX2DEC(D$1)+SUM($C$2:C58)) -> 0x4202903C
B59: ieee80211_user_ie_init | C59: 72 | D59: ="0x"&DEC2HEX(HEX2DEC(D$1)+SUM($C$2:C59)) -> 0x42029084
B60: ieee80211_ifattach | C60: 224 | D60: ="0x"&DEC2HEX(HEX2DEC(D$1)+SUM($C$2:C60)) -> 0x42029164
B61: ieee80211_ifdetach | C61: 24 | D61: ="0x"&DEC2HEX(HEX2DEC(D$1)+SUM($C$2:C61)) -> 0x4202917C
B62: wifi_destroy_softap | C62: 138 | D62: ="0x"&DEC2HEX(HEX2DEC(D$1)+SUM($C$2:C62)) -> 0x42029206
... B70: ieee80211_is_robust_mgmt_frm | C70: 74 | D70: ="0x"&DEC2HEX(HEX2DEC(D$1)+SUM($C$2:C70)) -> 0x420296E8
...

Sheet .libwpa-suppl
A1: os_xtensa.c.obj | D1: 42044778
B2: os_get_time | C2: 36 | D2: ="0x"&DEC2HEX(HEX2DEC(D$1)+SUM($C$2:C2)) -> 0x4204479C
B3: os_get_random | C3: 16 | D3: ="0x"&DEC2HEX(HEX2DEC(D$1)+SUM($C$2:C3)) -> 0x420447AC
B4: os_sleep | C4: 48 | D4: ="0x"&DEC2HEX(HEX2DEC(D$1)+SUM($C$2:C4)) -> 0x420447DC
A5: eloop.c.obj
B6: eloop_run_timer | C6: 32 | D6: ="0x"&DEC2HEX(HEX2DEC(D$1)+SUM($C$2:C6)) -> 0x420447FC
B7: eloop_remove_timeout | C7: 132 | D7: ="0x"&DEC2HEX(HEX2DEC(D$1)+SUM($C$2:C7)) -> 0x42044880
B8: os_timer_disarm.constprop.0 | C8: 22 | D8: ="0x"&DEC2HEX(HEX2DEC(D$1)+SUM($C$2:C8)) -> 0x42044896
B9: eloop_init | C9: 114 | D9: ="0x"&DEC2HEX(HEX2DEC(D$1)+SUM($C$2:C9)) -> 0x42044908
B10: eloop_register_timeout | C10: 334 | D10: ="0x"&DEC2HEX(HEX2DEC(D$1)+SUM($C$2:C10)) -> 0x42044A56
B11: eloop_cancel_timeout | C11: 110 | D11: ="0x"&DEC2HEX(HEX2DEC(D$1)+SUM($C$2:C11)) -> 0x42044AC4
B12: eloop_run | C12: 250 | D12: ="0x"&DEC2HEX(HEX2DEC(D$1)+SUM($C$2:C12)) -> 0x42044BBE
B13: eloop_run_wrapper | C13: 14 | D13: ="0x"&DEC2HEX(HEX2DEC(D$1)+SUM($C$2:C13)) -> 0x42044BCC
A14: ap_config.c.obj
B15: hostapd_setup_wpa_psk | C15: 80 | D15: ="0x"&DEC2HEX(HEX2DEC(D$1)+SUM($C$2:C15)) -> 0x42044C1C
B16: hostapd_get_psk | C16: 86 | D16: ="0x"&DEC2HEX(HEX2DEC(D$1)+SUM($C$2:C16)) -> 0x42044C72
B17: hostapd_config_clear_wpa_psk | C17: 42 | D17: ="0x"&DEC2HEX(HEX2DEC(D$1)+SUM($C$2:C17)) -> 0x42044C9C
B18: hostapd_config_free_bss | C18: 26 | D18: ="0x"&DEC2HEX(HEX2DEC(D$1)+SUM($C$2:C18)) -> 0x42044CB6
A19: ieee802_1x.c.obj
A20: wpa_auth.c.obj
B21: wpa_auth_pmksa_free_cb | C21: 2 | D21: ="0x"&DEC2HEX(HEX2DEC(D$1)+SUM($C$2:C21)) -> 0x42044CB8
B22: wpa_free_sta_sm | C22: 110 | D22: ="0x"&DEC2HEX(HEX2DEC(D$1)+SUM($C$2:C22)) -> 0x42044D26
B23: wpa_group_init_gmk_and_counter | C23: 126 | D23: ="0x"&DEC2HEX(HEX2DEC(D$1)+SUM($C$2:C23)) -> 0x42044DA4
B24: wpa_gmk_to_gtk | C24: 112 | D24: ="0x"&DEC2HEX(HEX2DEC(D$1)+SUM($C$2:C24)) -> 0x42044E14
B25: wpa_replay_counter_valid | C25: 62 | D25: ="0x"&DEC2HEX(HEX2DEC(D$1)+SUM($C$2:C25)) -> 0x42044E52
B26: wpa_replay_counter_mark_invalid | C26: 62 | D26: ="0x"&DEC2HEX(HEX2DEC(D$1)+SUM($C$2:C26)) -> 0x42044E90
B27: wpa_verify_key_mic | C27: 172 | D27: ="0x"&DEC2HEX(HEX2DEC(D$1)+SUM($C$2:C27)) -> 0x42044F3C
B28: ieee80211w_kde_add | C28: 122 | D28: ="0x"&DEC2HEX(HEX2DEC(D$1)+SUM($C$2:C28)) -> 0x42044FB6
B29: resend_eapol_handle | C29: 32 | D29: ="0x"&DEC2HEX(HEX2DEC(D$1)+SUM($C$2:C29)) -> 0x42044FD6
B30: wpa_auth_set_key.part.0 | C30: 90 | D30: ="0x"&DEC2HEX(HEX2DEC(D$1)+SUM($C$2:C30)) -> 0x42045030
B31: sm_WPA_PTK_DISCONNECT_Enter.constprop.0 | C31: 38 | D31: ="0x"&DEC2HEX(HEX2DEC(D$1)+SUM($C$2:C31)) -> 0x42045056
B32: wpa_gtk_update.isra.0 | C32: 186 | D32: ="0x"&DEC2HEX(HEX2DEC(D$1)+SUM($C$2:C32)) -> 0x42045110
... B57: wpa_ap_remove | C57: 46 | D57: ="0x"&DEC2HEX(HEX2DEC(D$1)+SUM($C$2:C57)) -> 0x420467BA
A58: wpa_auth_ie.c.obj
B59: wpa_write_rsn_ie | C59: 508 | D59: ="0x"&DEC2HEX(HEX2DEC(D$1)+SUM($C$2:C59)) -> 0x420469B6
B60: wpa_write_rsnxe | C60: 60 | D60: ="0x"&DEC2HEX(HEX2DEC(D$1)+SUM($C$2:C60)) -> 0x420469F2
B61: wpa_auth_gen_wpa_ie | C61: 366 | D61: ="0x"&DEC2HEX(HEX2DEC(D$1)+SUM($C$2:C61)) -> 0x42046B60
B62: wpa_add_kde | C62: 122 | D62: ="0x"&DEC2HEX(HEX2DEC(D$1)+SUM($C$2:C62)) -> 0x42046BDA
B63: wpa_validate_wpa_ie | C63: 580 | D63: ="0x"&DEC2HEX(HEX2DEC(D$1)+SUM($C$2:C63)) -> 0x42046E1E
B64: wpa_parse_kde_ies | C64: 398 | D64: ="0x"&DEC2HEX(HEX2DEC(D$1)+SUM($C$2:C64)) -> 0x42046FAC
...

Sheet .smoltcp
C1: 420511c8
A2: smoltcp::iface::interface::Interface::poll | B2: 612 | C2: 0x42051d5c-0x42051ecd
A3: smoltcp::iface::interface::Interface::poll_at | B3: 1370 | C3: ="0x"&DEC2HEX(HEX2DEC(C$1)+SUM($B$2:B3)) -> 0x42051986
A4: smoltcp::iface::interface::Interface::set_hardware_addr | B4: 60 | C4: ="0x"&DEC2HEX(HEX2DEC(C$1)+SUM($B$2:B4)) -> 0x420519C2
A5: smoltcp::iface::interface::InterfaceInner::check_ip_addrs | B5: 72 | C5: ="0x"&DEC2HEX(HEX2DEC(C$1)+SUM($B$2:B5)) -> 0x42051A0A
A6: smoltcp::iface::interface::InterfaceInner::dispatch_ip | B6: 798 | C6: ="0x"&DEC2HEX(HEX2DEC(C$1)+SUM($B$2:B6)) -> 0x42051D28
A7: smoltcp::iface::interface::InterfaceInner::get_source_address | B7: 52 | C7: ="0x"&DEC2HEX(HEX2DEC(C$1)+SUM($B$2:B7)) -> 0x42051D5C
A8: smoltcp::iface::interface::InterfaceInner::has_neighbor | B8: 370 | C8: ="0x"&DEC2HEX(HEX2DEC(C$1)+SUM($B$2:B8)) -> 0x42051ECE
A9: smoltcp::iface::interface::InterfaceInner::is_broadcast | B9: 216 | C9: ="0x"&DEC2HEX(HEX2DEC(C$1)+SUM($B$2:B9)) -> 0x42051FA6
A10: smoltcp::iface::interface::InterfaceInner::route | B10: 252 | C10: ="0x"&DEC2HEX(HEX2DEC(C$1)+SUM($B$2:B10)) -> 0x420520A2
A11: smoltcp::iface::interface::ethernet | C11: ="0x"&DEC2HEX(HEX2DEC(C$1)+SUM($B$2:B11)) -> 0x420520A2
A12: impl smoltcp::iface::interface::InterfaceInner::process_ethernet | B12: 2528 | C12: ="0x"&DEC2HEX(HEX2DEC(C$1)+SUM($B$2:B12)) -> 0x42052A82
A13: smoltcp::iface::interface::ipv4 | C13: ="0x"&DEC2HEX(HEX2DEC(C$1)+SUM($B$2:B13)) -> 0x42052A82
A14: impl::smoltcp::iface::interface::InterfaceInner::icmpv4_reply | B14: 798 | C14: ="0x"&DEC2HEX(HEX2DEC(C$1)+SUM($B$2:B14)) -> 0x42052DA0
A15: smoltcp::iface::neighbor::Cache::new | B15: 72 | C15: ="0x"&DEC2HEX(HEX2DEC(C$1)+SUM($B$2:B15)) -> 0x42052DE8
A16: smoltcp::iface::neighbor::Cache::fill | B16: 634 | C16: ="0x"&DEC2HEX(HEX2DEC(C$1)+SUM($B$2:B16)) -> 0x42053062
A17: smoltcp::iface::neighbor::Cache::lookup | B17: 230 | C17: ="0x"&DEC2HEX(HEX2DEC(C$1)+SUM($B$2:B17)) -> 0x42053148
A18: smoltcp::iface::packet::Packet::emit_payload | B18: 324 | C18: ="0x"&DEC2HEX(HEX2DEC(C$1)+SUM($B$2:B18)) -> 0x4205328C
A19: smoltcp::iface::route::Routes::new | B19: 64 | C19: ="0x"&DEC2HEX(HEX2DEC(C$1)+SUM($B$2:B19)) -> 0x420532CC
A20: smoltcp::iface::route::Routes::add_default_ipv4_route | B20: 302 | C20: ="0x"&DEC2HEX(HEX2DEC(C$1)+SUM($B$2:B20)) -> 0x420533FA
A21: smoltcp::iface::route::Routes::remove_default_ipv4_route | B21: 188 | C21: ="0x"&DEC2HEX(HEX2DEC(C$1)+SUM($B$2:B21)) -> 0x420534B6
A22: smoltcp::iface::route::Routes::lookup | B22: 524 | C22: ="0x"&DEC2HEX(HEX2DEC(C$1)+SUM($B$2:B22)) -> 0x420536C2
A23: smoltcp::iface::socket_set::SocketSet::add::put | B23: 140 | C23: ="0x"&DEC2HEX(HEX2DEC(C$1)+SUM($B$2:B23)) -> 0x4205374E
A24: smoltcp::iface::socket_set::SocketSet::remove | B24: 70 | C24: ="0x"&DEC2HEX(HEX2DEC(C$1)+SUM($B$2:B24)) -> 0x42053794
C25: ="0x"&DEC2HEX(HEX2DEC(C$1)+SUM($B$2:B25)) -> 0x42053794
A26: smoltcp::socket::dhcpv4::Socket::dispatch | B26: 1892 | C26: ="0x"&DEC2HEX(HEX2DEC(C$1)+SUM($B$2:B26)) -> 0x42053EF8
A27: smoltcp::socket::dhcpv4::Socket::parse_ack | B27: 756 | C27: ="0x"&DEC2HEX(HEX2DEC(C$1)+SUM($B$2:B27)) -> 0x420541EC
A28: smoltcp::socket::dhcpv4::Socket::poll | B28: 702 | C28: ="0x"&DEC2HEX(HEX2DEC(C$1)+SUM($B$2:B28)) -> 0x420544AA
A29: smoltcp::socket::dhcpv4::Socket::process | B29: 846 | C29: ="0x"&DEC2HEX(HEX2DEC(C$1)+SUM($B$2:B29)) -> 0x420547F8
A30: smoltcp::socket::dhcpv4::Socket::reset | B30: 156 | C30: ="0x"&DEC2HEX(HEX2DEC(C$1)+SUM($B$2:B30)) -> 0x42054894
A31: smoltcp::socket::dhcpv4::Config as core::cmp::PartialEq::eq | B31: 244 | C31: ="0x"&DEC2HEX(HEX2DEC(C$1)+SUM($B$2:B31)) -> 0x42054988
A32: core::ptr::drop_in_place smoltcp::socket::dhcpv4::ClientState | B32: 30 | C32: ="0x"&DEC2HEX(HEX2DEC(C$1)+SUM($B$2:B32)) -> 0x420549A6
A33: smoltcp::socket::udp::Socket::accepts | B33: 256 | C33: ="0x"&DEC2HEX(HEX2DEC(C$1)+SUM($B$2:B33)) -> 0x42054AA6
A34: smoltcp::socket::udp::Socket::process | B34: 150 | C34: ="0x"&DEC2HEX(HEX2DEC(C$1)+SUM($B$2:B34)) -> 0x42054B3C
A35: smoltcp::socket::udp::Socket::recv_slice | B35: 270 | C35: ="0x"&DEC2HEX(HEX2DEC(C$1)+SUM($B$2:B35)) -> 0x42054C4A
A36: smoltcp::socket::udp::Socket::register_recv_waker | B36: 80 | C36: ="0x"&DEC2HEX(HEX2DEC(C$1)+SUM($B$2:B36)) -> 0x42054C9A
A37: smoltcp::socket::udp::Socket::register_send_waker | B37: 80 | C37: ="0x"&DEC2HEX(HEX2DEC(C$1)+SUM($B$2:B37)) -> 0x42054CEA
... A39: smoltcp::socket::waker::WakerRegistration::wake | B39: 18 | C39: ="0x"&DEC2HEX(HEX2DEC(C$1)+SUM($B$2:B39)) -> 0x42054ED6
C40: ="0x"&DEC2HEX(HEX2DEC(C$1)+SUM($B$2:B40)) -> 0x42054ED6
A41: smoltcp::storage::packet_buffer::PacketBuffer::enqueue | B41: 430 | C41: ="0x"&DEC2HEX(HEX2DEC(C$1)+SUM($B$2:B41)) -> 0x42055084
...

Sheet core-text
A1: .core
B2: strlen | C2: 24
B4: alloc::alloc::handle_alloc_error | C4: 2
B5: alloc::raw_vec::finish_grow | C5: 98
B6: alloc::raw_vec::RawVec::grow_one | C6: 144
B7: alloc::raw_vec::handle_error | C7: 2
B8: alloc::collections::vec_deque::VecDeque::grow | C8: 152
B10: core::alloc::layout::Layout::is_size_align_valid | C10: 28
B12: core::cell::once::OnceCell::try_init
B13: core::cell::once::OnceCell::try_init | C13: 116
B14: core::cell::once::OnceCell::try_init | C14: 220
B15: core::cell::panic_already_borrowed
B16: core::cell::panic_already_mutably_borrowed | C16: 2
B18: core::slice::index::slice_end_index_len_fail::do_panic::runtime
B19: core::slice::index::slice_index_order_fail::do_panic::runtime
B20: core::slice::index::slice_start_index_len_fail::do_panic::runtime | C20: 2
B22: core::slice
B23: impl copy_from_slice::len_mismatch_fail::do_panic::runtime | C23: 2
D25: =SUM(C$2:$C24) -> 792 | E25: ="0x"&DEC2HEX(D25) -> 0x318
A27: .text
B28: embassy_executor::raw::TaskStorage::poll | C28: 146
B29: embassy_executor::raw::TaskStorage::poll | C29: 108
B30: embassy_executor::raw::TaskStorage::poll | C30: 1338
B31: embassy_executor::raw::TaskStorage::poll | C31: 922
B32: embassy_executor::raw::TaskStorage::poll | C32: 1724
B33: main | C33: 16
D34: =SUM(C$28:$C33) -> 4254 | E34: ="0x"&DEC2HEX(D34) -> 0x109E
